<?xml version="1.0"?>
<robot name="raider_3197" xmlns:xacro="http://ros.org/wiki/xacro">
	<!-- Constants -->
	<xacro:property name="pi" value="3.1415926535897931"/>

	<!-- Import macros -->

	<xacro:include filename="$(find raider_3197_description)/urdf/wheel_front_joint.xacro" />
	<xacro:include filename="$(find raider_3197_description)/urdf/wheel_front_link.xacro" />
	<xacro:include filename="$(find raider_3197_description)/urdf/wheel_rear_joint.xacro" />
	<xacro:include filename="$(find raider_3197_description)/urdf/wheel_rear_link.xacro" />

	<!-- Import all Gazebo-customization elements, including Gazebo colors -->
	<xacro:include filename="$(find raider_3197_description)/urdf/raider_3197.gazebo" />
	<!-- Import Rviz colors -->
	<xacro:include filename="$(find raider_3197_description)/urdf/materials.xacro" />

	<!-- Used for fixing robot to Gazebo 'base_link' -->
	<link name="world"/>

	<joint name="fixed" type="floating">
		<parent link="world"/>
		<child link="base_link"/>
	</joint>

	<!-- Base Link -->
	<link name="base_link">
		<inertial>
			<mass value="1.0" />
			<inertia ixx="0.004167" iyy="0.011042" izz="0.01354" ixy="0.0" ixz="0.0" iyz="0.0" />
		</inertial>

		<collision name='collision_base_link'>
			<geometry>
				<box size="0.350 0.200 0.075"/>
			</geometry>
		</collision>

		<visual name='visual_base_link'>
			<geometry>
				<box size="0.350 0.200 0.075"/>
			</geometry>
			<material name="orange"/>
		</visual>
	</link>

	<xacro:wheel_front_joint suffix="wheel_front_left" parent="base_link" xyz="0.175 0.11 -0.0375" rpy="${pi/2} ${pi/2} 0" />
	<xacro:wheel_front_link suffix="wheel_front_left" />
	<xacro:wheel_front_joint suffix="wheel_front_right" parent="base_link" xyz="0.175 -0.11 -0.0375" rpy="${pi/2} ${pi/2} 0" />
	<xacro:wheel_front_link suffix="wheel_front_right" />

	<xacro:wheel_rear_joint suffix="wheel_rear_left" parent="base_link" xyz="-0.175 0.12 -0.0375" rpy="${pi/2} ${pi/2} 0" />
	<xacro:wheel_rear_link suffix="wheel_rear_left" />
	<xacro:wheel_rear_joint suffix="wheel_rear_right" parent="base_link" xyz="-0.175 -0.12 -0.0375" rpy="${pi/2} ${pi/2} 0" />
	<xacro:wheel_rear_link suffix="wheel_rear_right" />
</robot>
